<sdf version='1.7'>
  <world name='default'>
    <light name='sun' type='directional'>
      <cast_shadows>1</cast_shadows>
      <pose>0 0 10 0 -0 0</pose>
      <diffuse>0.8 0.8 0.8 1</diffuse>
      <specular>0.2 0.2 0.2 1</specular>
      <attenuation>
        <range>1000</range>
        <constant>0.9</constant>
        <linear>0.01</linear>
        <quadratic>0.001</quadratic>
      </attenuation>
      <direction>-0.5 0.1 -0.9</direction>
      <spot>
        <inner_angle>0</inner_angle>
        <outer_angle>0</outer_angle>
        <falloff>0</falloff>
      </spot>
    </light>
    <model name='ground_plane'>
      <static>1</static>
      <link name='link'>
        <collision name='collision'>
          <geometry>
            <plane>
              <normal>0 0 1</normal>
              <size>100 100</size>
            </plane>
          </geometry>
          <surface>
            <contact>
              <collide_bitmask>65535</collide_bitmask>
              <ode/>
            </contact>
            <friction>
              <ode>
                <mu>100</mu>
                <mu2>50</mu2>
              </ode>
              <torsional>
                <ode/>
              </torsional>
            </friction>
            <bounce/>
          </surface>
          <max_contacts>10</max_contacts>
        </collision>
        <visual name='visual'>
          <cast_shadows>0</cast_shadows>
          <geometry>
            <plane>
              <normal>0 0 1</normal>
              <size>100 100</size>
            </plane>
          </geometry>
          <material>
            <script>
              <uri>file://media/materials/scripts/gazebo.material</uri>
              <name>Gazebo/Grey</name>
            </script>
          </material>
        </visual>
        <self_collide>0</self_collide>
        <enable_wind>0</enable_wind>
        <kinematic>0</kinematic>
      </link>
    </model>
    <model name='asphalt_plane'>
      <static>1</static>
      <link name='link'>
        <collision name='collision'>
          <geometry>
            <box>
              <size>20 20 0.1</size>
            </box>
          </geometry>
          <max_contacts>10</max_contacts>
          <surface>
            <contact>
              <ode/>
            </contact>
            <bounce/>
            <friction>
              <torsional>
                <ode/>
              </torsional>
              <ode/>
            </friction>
          </surface>
        </collision>
        <visual name='visual'>
          <cast_shadows>0</cast_shadows>
          <geometry>
            <box>
              <size>20 20 0.1</size>
            </box>
          </geometry>
          <material>
            <script>
              <uri>model://asphalt_plane/materials/scripts</uri>
              <uri>model://asphalt_plane/materials/textures</uri>
              <name>vrc/asphalt</name>
            </script>
          </material>
        </visual>
        <self_collide>0</self_collide>
        <enable_wind>0</enable_wind>
        <kinematic>0</kinematic>
      </link>
    </model>
    <physics name='default_physics' default='0' type='ode'>
      <ode>
        <solver>
          <type>quick</type>
          <iters>10</iters>
          <sor>1.3</sor>
          <use_dynamic_moi_rescaling>0</use_dynamic_moi_rescaling>
        </solver>
        <constraints>
          <cfm>0</cfm>
          <erp>0.2</erp>
          <contact_max_correcting_vel>100</contact_max_correcting_vel>
          <contact_surface_layer>0.001</contact_surface_layer>
        </constraints>
      </ode>
      <max_step_size>0.004</max_step_size>
      <real_time_factor>1</real_time_factor>
      <real_time_update_rate>250</real_time_update_rate>
    </physics>
    <gravity>0 0 -9.8066</gravity>
    <magnetic_field>6e-06 2.3e-05 -4.2e-05</magnetic_field>
    <atmosphere type='adiabatic'/>
    <scene>
      <ambient>0.4 0.4 0.4 1</ambient>
      <background>0.7 0.7 0.7 1</background>
      <shadows>1</shadows>
    </scene>
    <wind/>
    <spherical_coordinates>
      <surface_model>EARTH_WGS84</surface_model>
      <latitude_deg>0</latitude_deg>
      <longitude_deg>0</longitude_deg>
      <elevation>0</elevation>
      <heading_deg>0</heading_deg>
    </spherical_coordinates>
    <model name='standard_vtol'>
      <pose>1.01 0.98 0.83 0 -0 0</pose>
      <link name='base_link'>
        <pose>0 0 0 0 -0 0</pose>
        <inertial>
          <pose>0 0 0 0 -0 0</pose>
          <mass>5</mass>
          <inertia>
            <ixx>0.477708</ixx>
            <ixy>0</ixy>
            <ixz>0</ixz>
            <iyy>0.341667</iyy>
            <iyz>0</iyz>
            <izz>0.811042</izz>
          </inertia>
        </inertial>
        <collision name='base_link_collision'>
          <pose>0 0 -0.07 0 -0 0</pose>
          <geometry>
            <box>
              <size>0.55 2.144 0.05</size>
            </box>
          </geometry>
          <surface>
            <contact>
              <ode>
                <kp>100000</kp>
                <kd>1</kd>
                <max_vel>0.1</max_vel>
                <min_depth>0.001</min_depth>
              </ode>
            </contact>
            <friction>
              <ode/>
              <torsional>
                <ode/>
              </torsional>
            </friction>
            <bounce/>
          </surface>
          <max_contacts>10</max_contacts>
        </collision>
        <visual name='base_link_visual'>
          <pose>0.53 -1.072 -0.1 1.5708 -0 -3.14159</pose>
          <geometry>
            <mesh>
              <scale>0.001 0.001 0.001</scale>
              <uri>model://standard_vtol/meshes/x8_wing.dae</uri>
            </mesh>
          </geometry>
          <material>
            <script>
              <name>Gazebo/DarkGrey</name>
              <uri>__default__</uri>
            </script>
          </material>
        </visual>
        <visual name='left_motor_column'>
          <pose>0 0.35 0.01 0 -0 0</pose>
          <geometry>
            <box>
              <size>0.74 0.03 0.03</size>
            </box>
          </geometry>
          <material>
            <script>
              <name>Gazebo/DarkGrey</name>
              <uri>__default__</uri>
            </script>
          </material>
        </visual>
        <visual name='right_motor_column'>
          <pose>0 -0.35 0.01 0 -0 0</pose>
          <geometry>
            <box>
              <size>0.74 0.03 0.03</size>
            </box>
          </geometry>
          <material>
            <script>
              <name>Gazebo/DarkGrey</name>
              <uri>__default__</uri>
            </script>
          </material>
        </visual>
        <visual name='m0'>
          <pose>-0.35 0.35 0.045 0 -0 0</pose>
          <geometry>
            <cylinder>
              <length>0.035</length>
              <radius>0.02</radius>
            </cylinder>
          </geometry>
          <material>
            <script>
              <name>Gazebo/DarkGrey</name>
              <uri>__default__</uri>
            </script>
          </material>
        </visual>
        <visual name='m1'>
          <pose>-0.35 -0.35 0.045 0 -0 0</pose>
          <geometry>
            <cylinder>
              <length>0.035</length>
              <radius>0.02</radius>
            </cylinder>
          </geometry>
          <material>
            <script>
              <name>Gazebo/DarkGrey</name>
              <uri>__default__</uri>
            </script>
          </material>
        </visual>
        <visual name='m2'>
          <pose>0.35 -0.35 0.045 0 -0 0</pose>
          <geometry>
            <cylinder>
              <length>0.035</length>
              <radius>0.02</radius>
            </cylinder>
          </geometry>
          <material>
            <script>
              <name>Gazebo/DarkGrey</name>
              <uri>__default__</uri>
            </script>
          </material>
        </visual>
        <visual name='m3'>
          <pose>0.35 0.35 0.045 0 -0 0</pose>
          <geometry>
            <cylinder>
              <length>0.035</length>
              <radius>0.02</radius>
            </cylinder>
          </geometry>
          <material>
            <script>
              <name>Gazebo/DarkGrey</name>
              <uri>__default__</uri>
            </script>
          </material>
        </visual>
        <gravity>1</gravity>
        <velocity_decay/>
        <self_collide>0</self_collide>
        <enable_wind>0</enable_wind>
        <kinematic>0</kinematic>
      </link>
      <link name='standard_vtol/imu_link'>
        <pose>0 0 0 0 -0 0</pose>
        <inertial>
          <pose>0 0 0 0 -0 0</pose>
          <mass>0.015</mass>
          <inertia>
            <ixx>1e-05</ixx>
            <ixy>0</ixy>
            <ixz>0</ixz>
            <iyy>1e-05</iyy>
            <iyz>0</iyz>
            <izz>1e-05</izz>
          </inertia>
        </inertial>
        <self_collide>0</self_collide>
        <enable_wind>0</enable_wind>
        <kinematic>0</kinematic>
      </link>
      <joint name='standard_vtol/imu_joint' type='revolute'>
        <child>standard_vtol/imu_link</child>
        <parent>base_link</parent>
        <axis>
          <xyz expressed_in='__model__'>1 0 0</xyz>
          <limit>
            <lower>0</lower>
            <upper>0</upper>
            <effort>0</effort>
            <velocity>0</velocity>
          </limit>
          <dynamics>
            <spring_reference>0</spring_reference>
            <spring_stiffness>0</spring_stiffness>
          </dynamics>
        </axis>
      </joint>
      <frame name='airspeed::__model__' attached_to='airspeed::link'>
        <pose relative_to='__model__'>0 0 0 0 -0 0</pose>
      </frame>
      <link name='airspeed::link'>
        <pose relative_to='airspeed::__model__'>0 0 0 0 -0 0</pose>
        <inertial>
          <pose>0 0 0 0 -0 0</pose>
          <mass>0.015</mass>
          <inertia>
            <ixx>1e-05</ixx>
            <ixy>0</ixy>
            <ixz>0</ixz>
            <iyy>1e-05</iyy>
            <iyz>0</iyz>
            <izz>1e-05</izz>
          </inertia>
        </inertial>
        <visual name='visual'>
          <pose>0 0 0 0 1.57 0</pose>
          <geometry>
            <cylinder>
              <radius>0.004</radius>
              <length>0.08</length>
            </cylinder>
          </geometry>
          <material>
            <script>
              <name>Gazebo/Black</name>
              <uri>__default__</uri>
            </script>
          </material>
        </visual>
        <sensor name='airspeed' type='gps'>
          <pose>0 0 0 0 -0 0</pose>
          <update_rate>5</update_rate>
          <always_on>1</always_on>
          <visualize>0</visualize>
          <plugin name='airspeed_plugin' filename='libgazebo_airspeed_plugin.so'>
            <robotNamespace/>
          </plugin>
          <gps/>
        </sensor>
        <self_collide>0</self_collide>
        <enable_wind>0</enable_wind>
        <kinematic>0</kinematic>
      </link>
      <joint name='airspeed_joint' type='fixed'>
        <child>airspeed::link</child>
        <parent>base_link</parent>
      </joint>
      <link name='rotor_0'>
        <pose>0.35 -0.35 0.07 0 -0 0</pose>
        <inertial>
          <pose>0 0 0 0 -0 0</pose>
          <mass>0.005</mass>
          <inertia>
            <ixx>9.75e-07</ixx>
            <ixy>0</ixy>
            <ixz>0</ixz>
            <iyy>0.000166704</iyy>
            <iyz>0</iyz>
            <izz>0.000167604</izz>
          </inertia>
        </inertial>
        <collision name='rotor_0_collision'>
          <pose>0 0 0 0 -0 0</pose>
          <geometry>
            <cylinder>
              <length>0.005</length>
              <radius>0.1</radius>
            </cylinder>
          </geometry>
          <surface>
            <contact>
              <ode/>
            </contact>
            <friction>
              <ode/>
              <torsional>
                <ode/>
              </torsional>
            </friction>
            <bounce/>
          </surface>
          <max_contacts>10</max_contacts>
        </collision>
        <visual name='rotor_0_visual'>
          <pose>0 0 0 0 -0 0</pose>
          <geometry>
            <mesh>
              <scale>1 1 1</scale>
              <uri>model://standard_vtol/meshes/iris_prop_ccw.dae</uri>
            </mesh>
          </geometry>
          <material>
            <script>
              <name>Gazebo/Blue</name>
              <uri>__default__</uri>
            </script>
          </material>
        </visual>
        <gravity>1</gravity>
        <velocity_decay/>
        <self_collide>0</self_collide>
        <enable_wind>0</enable_wind>
        <kinematic>0</kinematic>
      </link>
      <joint name='rotor_0_joint' type='revolute'>
        <child>rotor_0</child>
        <parent>base_link</parent>
        <axis>
          <xyz expressed_in='__model__'>0 0 1</xyz>
          <limit>
            <lower>-1e+16</lower>
            <upper>1e+16</upper>
          </limit>
          <dynamics>
            <spring_reference>0</spring_reference>
            <spring_stiffness>0</spring_stiffness>
          </dynamics>
        </axis>
      </joint>
      <link name='rotor_1'>
        <pose>-0.35 0.35 0.07 0 -0 0</pose>
        <inertial>
          <pose>0 0 0 0 -0 0</pose>
          <mass>0.005</mass>
          <inertia>
            <ixx>9.75e-07</ixx>
            <ixy>0</ixy>
            <ixz>0</ixz>
            <iyy>0.000166704</iyy>
            <iyz>0</iyz>
            <izz>0.000167604</izz>
          </inertia>
        </inertial>
        <collision name='rotor_1_collision'>
          <pose>0 0 0 0 -0 0</pose>
          <geometry>
            <cylinder>
              <length>0.005</length>
              <radius>0.1</radius>
            </cylinder>
          </geometry>
          <surface>
            <contact>
              <ode/>
            </contact>
            <friction>
              <ode/>
              <torsional>
                <ode/>
              </torsional>
            </friction>
            <bounce/>
          </surface>
          <max_contacts>10</max_contacts>
        </collision>
        <visual name='rotor_1_visual'>
          <pose>0 0 0 0 -0 0</pose>
          <geometry>
            <mesh>
              <scale>1 1 1</scale>
              <uri>model://standard_vtol/meshes/iris_prop_ccw.dae</uri>
            </mesh>
          </geometry>
          <material>
            <script>
              <name>Gazebo/Blue</name>
              <uri>__default__</uri>
            </script>
          </material>
        </visual>
        <gravity>1</gravity>
        <velocity_decay/>
        <self_collide>0</self_collide>
        <enable_wind>0</enable_wind>
        <kinematic>0</kinematic>
      </link>
      <joint name='rotor_1_joint' type='revolute'>
        <child>rotor_1</child>
        <parent>base_link</parent>
        <axis>
          <xyz expressed_in='__model__'>0 0 1</xyz>
          <limit>
            <lower>-1e+16</lower>
            <upper>1e+16</upper>
          </limit>
          <dynamics>
            <spring_reference>0</spring_reference>
            <spring_stiffness>0</spring_stiffness>
          </dynamics>
        </axis>
      </joint>
      <link name='rotor_2'>
        <pose>0.35 0.35 0.07 0 -0 0</pose>
        <inertial>
          <pose>0 0 0 0 -0 0</pose>
          <mass>0.005</mass>
          <inertia>
            <ixx>9.75e-07</ixx>
            <ixy>0</ixy>
            <ixz>0</ixz>
            <iyy>0.000166704</iyy>
            <iyz>0</iyz>
            <izz>0.000167604</izz>
          </inertia>
        </inertial>
        <collision name='rotor_2_collision'>
          <pose>0 0 0 0 -0 0</pose>
          <geometry>
            <cylinder>
              <length>0.005</length>
              <radius>0.1</radius>
            </cylinder>
          </geometry>
          <surface>
            <contact>
              <ode/>
            </contact>
            <friction>
              <ode/>
              <torsional>
                <ode/>
              </torsional>
            </friction>
            <bounce/>
          </surface>
          <max_contacts>10</max_contacts>
        </collision>
        <visual name='rotor_2_visual'>
          <pose>0 0 0 0 -0 0</pose>
          <geometry>
            <mesh>
              <scale>1 1 1</scale>
              <uri>model://standard_vtol/meshes/iris_prop_ccw.dae</uri>
            </mesh>
          </geometry>
          <material>
            <script>
              <name>Gazebo/Blue</name>
              <uri>__default__</uri>
            </script>
          </material>
        </visual>
        <gravity>1</gravity>
        <velocity_decay/>
        <self_collide>0</self_collide>
        <enable_wind>0</enable_wind>
        <kinematic>0</kinematic>
      </link>
      <joint name='rotor_2_joint' type='revolute'>
        <child>rotor_2</child>
        <parent>base_link</parent>
        <axis>
          <xyz expressed_in='__model__'>0 0 1</xyz>
          <limit>
            <lower>-1e+16</lower>
            <upper>1e+16</upper>
          </limit>
          <dynamics>
            <spring_reference>0</spring_reference>
            <spring_stiffness>0</spring_stiffness>
          </dynamics>
        </axis>
      </joint>
      <link name='rotor_3'>
        <pose>-0.35 -0.35 0.07 0 -0 0</pose>
        <inertial>
          <pose>0 0 0 0 -0 0</pose>
          <mass>0.005</mass>
          <inertia>
            <ixx>9.75e-07</ixx>
            <ixy>0</ixy>
            <ixz>0</ixz>
            <iyy>0.000166704</iyy>
            <iyz>0</iyz>
            <izz>0.000167604</izz>
          </inertia>
        </inertial>
        <collision name='rotor_3_collision'>
          <pose>0 0 0 0 -0 0</pose>
          <geometry>
            <cylinder>
              <length>0.005</length>
              <radius>0.1</radius>
            </cylinder>
          </geometry>
          <surface>
            <contact>
              <ode/>
            </contact>
            <friction>
              <ode/>
              <torsional>
                <ode/>
              </torsional>
            </friction>
            <bounce/>
          </surface>
          <max_contacts>10</max_contacts>
        </collision>
        <visual name='rotor_3_visual'>
          <pose>0 0 0 0 -0 0</pose>
          <geometry>
            <mesh>
              <scale>1 1 1</scale>
              <uri>model://standard_vtol/meshes/iris_prop_ccw.dae</uri>
            </mesh>
          </geometry>
          <material>
            <script>
              <name>Gazebo/Blue</name>
              <uri>__default__</uri>
            </script>
          </material>
        </visual>
        <gravity>1</gravity>
        <velocity_decay/>
        <self_collide>0</self_collide>
        <enable_wind>0</enable_wind>
        <kinematic>0</kinematic>
      </link>
      <joint name='rotor_3_joint' type='revolute'>
        <child>rotor_3</child>
        <parent>base_link</parent>
        <axis>
          <xyz expressed_in='__model__'>0 0 1</xyz>
          <limit>
            <lower>-1e+16</lower>
            <upper>1e+16</upper>
          </limit>
          <dynamics>
            <spring_reference>0</spring_reference>
            <spring_stiffness>0</spring_stiffness>
          </dynamics>
        </axis>
      </joint>
      <link name='rotor_puller'>
        <pose>-0.22 0 0 0 1.57 0</pose>
        <inertial>
          <pose>0 0 0 0 -0 0</pose>
          <mass>0.005</mass>
          <inertia>
            <ixx>9.75e-07</ixx>
            <ixy>0</ixy>
            <ixz>0</ixz>
            <iyy>0.000166704</iyy>
            <iyz>0</iyz>
            <izz>0.000167604</izz>
          </inertia>
        </inertial>
        <collision name='rotor_puller_collision'>
          <pose>0 0 -0.04 0 -0 0</pose>
          <geometry>
            <cylinder>
              <length>0.005</length>
              <radius>0.06</radius>
            </cylinder>
          </geometry>
          <surface>
            <contact>
              <ode/>
            </contact>
            <friction>
              <ode/>
              <torsional>
                <ode/>
              </torsional>
            </friction>
            <bounce/>
          </surface>
          <max_contacts>10</max_contacts>
        </collision>
        <visual name='rotor_puller_visual'>
          <pose>0 0 -0.04 0 -0 0</pose>
          <geometry>
            <mesh>
              <scale>0.8 0.8 0.8</scale>
              <uri>model://standard_vtol/meshes/iris_prop_ccw.dae</uri>
            </mesh>
          </geometry>
          <material>
            <script>
              <name>Gazebo/Blue</name>
              <uri>__default__</uri>
            </script>
          </material>
        </visual>
        <gravity>1</gravity>
        <velocity_decay/>
        <self_collide>0</self_collide>
        <enable_wind>0</enable_wind>
        <kinematic>0</kinematic>
      </link>
      <joint name='rotor_puller_joint' type='revolute'>
        <child>rotor_puller</child>
        <parent>base_link</parent>
        <axis>
          <xyz expressed_in='__model__'>1 0 0</xyz>
          <limit>
            <lower>-1e+16</lower>
            <upper>1e+16</upper>
          </limit>
          <dynamics>
            <spring_reference>0</spring_reference>
            <spring_stiffness>0</spring_stiffness>
          </dynamics>
        </axis>
      </joint>
      <link name='left_elevon'>
        <inertial>
          <mass>1e-08</mass>
          <inertia>
            <ixx>1e-06</ixx>
            <ixy>0</ixy>
            <iyy>1e-06</iyy>
            <ixz>0</ixz>
            <iyz>0</iyz>
            <izz>1e-06</izz>
          </inertia>
          <pose>0 0.3 0 0 -0 0</pose>
        </inertial>
        <visual name='left_elevon_visual'>
          <pose>-0.105 0.004 -0.034 1.5708 -0 -3.14159</pose>
          <geometry>
            <mesh>
              <scale>0.001 0.001 0.001</scale>
              <uri>model://standard_vtol/meshes/x8_elevon_left.dae</uri>
            </mesh>
          </geometry>
          <material>
            <script>
              <name>Gazebo/Blue</name>
              <uri>__default__</uri>
            </script>
          </material>
        </visual>
        <self_collide>0</self_collide>
        <enable_wind>0</enable_wind>
        <kinematic>0</kinematic>
      </link>
      <link name='right_elevon'>
        <inertial>
          <mass>1e-08</mass>
          <inertia>
            <ixx>1e-06</ixx>
            <ixy>0</ixy>
            <iyy>1e-06</iyy>
            <ixz>0</ixz>
            <iyz>0</iyz>
            <izz>1e-06</izz>
          </inertia>
          <pose>0 -0.6 0 0 -0 0</pose>
        </inertial>
        <visual name='right_elevon_visual'>
          <pose>0.281 -1.032 -0.034 1.5708 -0 -3.14159</pose>
          <geometry>
            <mesh>
              <scale>0.001 0.001 0.001</scale>
              <uri>model://standard_vtol/meshes/x8_elevon_right.dae</uri>
            </mesh>
          </geometry>
          <material>
            <script>
              <name>Gazebo/Blue</name>
              <uri>__default__</uri>
            </script>
          </material>
        </visual>
        <self_collide>0</self_collide>
        <enable_wind>0</enable_wind>
        <kinematic>0</kinematic>
      </link>
      <link name='elevator'>
        <inertial>
          <mass>1e-08</mass>
          <inertia>
            <ixx>1e-06</ixx>
            <ixy>0</ixy>
            <iyy>1e-06</iyy>
            <ixz>0</ixz>
            <iyz>0</iyz>
            <izz>1e-06</izz>
          </inertia>
          <pose>-0.5 0 0 0 -0 0</pose>
        </inertial>
        <self_collide>0</self_collide>
        <enable_wind>0</enable_wind>
        <kinematic>0</kinematic>
      </link>
      <link name='rudder'>
        <inertial>
          <mass>1e-08</mass>
          <inertia>
            <ixx>1e-06</ixx>
            <ixy>0</ixy>
            <iyy>1e-06</iyy>
            <ixz>0</ixz>
            <iyz>0</iyz>
            <izz>1e-06</izz>
          </inertia>
          <pose>-0.5 0 0.05 0 -0 0</pose>
        </inertial>
        <self_collide>0</self_collide>
        <enable_wind>0</enable_wind>
        <kinematic>0</kinematic>
      </link>
      <joint name='left_elevon_joint' type='revolute'>
        <parent>base_link</parent>
        <child>left_elevon</child>
        <pose>-0.18 0.6 -0.005 0 -0 0.265</pose>
        <axis>
          <xyz>0 1 0</xyz>
          <limit>
            <lower>-0.53</lower>
            <upper>0.53</upper>
          </limit>
          <dynamics>
            <damping>1</damping>
            <spring_reference>0</spring_reference>
            <spring_stiffness>0</spring_stiffness>
          </dynamics>
        </axis>
        <physics>
          <ode>
            <implicit_spring_damper>1</implicit_spring_damper>
            <limit>
              <cfm>0</cfm>
              <erp>0.2</erp>
            </limit>
          </ode>
        </physics>
      </joint>
      <joint name='right_elevon_joint' type='revolute'>
        <parent>base_link</parent>
        <child>right_elevon</child>
        <pose>-0.18 -0.6 -0.005 0 0 -0.265</pose>
        <axis>
          <xyz>0 1 0</xyz>
          <limit>
            <lower>-0.53</lower>
            <upper>0.53</upper>
          </limit>
          <dynamics>
            <damping>1</damping>
            <spring_reference>0</spring_reference>
            <spring_stiffness>0</spring_stiffness>
          </dynamics>
        </axis>
        <physics>
          <ode>
            <implicit_spring_damper>1</implicit_spring_damper>
            <limit>
              <cfm>0</cfm>
              <erp>0.2</erp>
            </limit>
          </ode>
        </physics>
      </joint>
      <joint name='elevator_joint' type='revolute'>
        <parent>base_link</parent>
        <child>elevator</child>
        <pose>-0.5 0 0 0 -0 0</pose>
        <axis>
          <xyz>0 1 0</xyz>
          <limit>
            <lower>-0.53</lower>
            <upper>0.53</upper>
          </limit>
          <dynamics>
            <damping>1</damping>
            <spring_reference>0</spring_reference>
            <spring_stiffness>0</spring_stiffness>
          </dynamics>
        </axis>
        <physics>
          <ode>
            <implicit_spring_damper>1</implicit_spring_damper>
            <limit>
              <cfm>0</cfm>
              <erp>0.2</erp>
            </limit>
          </ode>
        </physics>
      </joint>
      <joint name='rudder_joint' type='revolute'>
        <parent>base_link</parent>
        <child>rudder</child>
        <pose>-0.5 0 0.05 0 -0 0</pose>
        <axis>
          <xyz>1 0 0</xyz>
          <limit>
            <lower>-0.01</lower>
            <upper>0.01</upper>
          </limit>
          <dynamics>
            <damping>1</damping>
            <spring_reference>0</spring_reference>
            <spring_stiffness>0</spring_stiffness>
          </dynamics>
        </axis>
        <physics>
          <ode>
            <implicit_spring_damper>1</implicit_spring_damper>
            <limit>
              <cfm>0</cfm>
              <erp>0.2</erp>
            </limit>
          </ode>
        </physics>
      </joint>
      <frame name='gps::__model__' attached_to='gps::link'>
        <pose relative_to='__model__'>0 0 0 0 -0 0</pose>
      </frame>
      <link name='gps::link'>
        <pose relative_to='gps::__model__'>0 0 0 0 -0 0</pose>
        <inertial>
          <pose>0 0 0 0 -0 0</pose>
          <mass>0.015</mass>
          <inertia>
            <ixx>1e-05</ixx>
            <ixy>0</ixy>
            <ixz>0</ixz>
            <iyy>1e-05</iyy>
            <iyz>0</iyz>
            <izz>1e-05</izz>
          </inertia>
        </inertial>
        <visual name='visual'>
          <geometry>
            <cylinder>
              <radius>0.01</radius>
              <length>0.002</length>
            </cylinder>
          </geometry>
          <material>
            <script>
              <name>Gazebo/Black</name>
              <uri>__default__</uri>
            </script>
          </material>
        </visual>
        <sensor name='gps' type='gps'>
          <pose>0 0 0 0 -0 0</pose>
          <update_rate>5</update_rate>
          <always_on>1</always_on>
          <visualize>0</visualize>
          <plugin name='gps_plugin' filename='libgazebo_gps_plugin.so'>
            <robotNamespace/>
            <gpsNoise>1</gpsNoise>
            <gpsXYRandomWalk>2.0</gpsXYRandomWalk>
            <gpsZRandomWalk>4.0</gpsZRandomWalk>
            <gpsXYNoiseDensity>2.0e-4</gpsXYNoiseDensity>
            <gpsZNoiseDensity>4.0e-4</gpsZNoiseDensity>
            <gpsVXYNoiseDensity>0.2</gpsVXYNoiseDensity>
            <gpsVZNoiseDensity>0.4</gpsVZNoiseDensity>
          </plugin>
          <gps/>
        </sensor>
        <self_collide>0</self_collide>
        <enable_wind>0</enable_wind>
        <kinematic>0</kinematic>
      </link>
      <joint name='gps_joint' type='fixed'>
        <child>gps::link</child>
        <parent>base_link</parent>
      </joint>
      <plugin name='left_wing_lift' filename='libLiftDragPlugin.so'>
        <a0>0.05984281113</a0>
        <cla>4.752798721</cla>
        <cda>0.6417112299</cda>
        <cma>0.0</cma>
        <alpha_stall>0.3391428111</alpha_stall>
        <cla_stall>-3.85</cla_stall>
        <cda_stall>-0.9233984055</cda_stall>
        <cma_stall>0</cma_stall>
        <cp>-0.05 0.3 0.05</cp>
        <area>0.50</area>
        <air_density>1.2041</air_density>
        <forward>1 0 0</forward>
        <upward>0 0 1</upward>
        <link_name>base_link</link_name>
        <control_joint_name>left_elevon_joint</control_joint_name>
        <control_joint_rad_to_cl>-1.0</control_joint_rad_to_cl>
        <robotNamespace/>
        <windSubTopic>world_wind</windSubTopic>
      </plugin>
      <plugin name='right_wing_lift' filename='libLiftDragPlugin.so'>
        <a0>0.05984281113</a0>
        <cla>4.752798721</cla>
        <cda>0.6417112299</cda>
        <cma>0.0</cma>
        <alpha_stall>0.3391428111</alpha_stall>
        <cla_stall>-3.85</cla_stall>
        <cda_stall>-0.9233984055</cda_stall>
        <cma_stall>0</cma_stall>
        <cp>-0.05 -0.3 0.05</cp>
        <area>0.50</area>
        <air_density>1.2041</air_density>
        <forward>1 0 0</forward>
        <upward>0 0 1</upward>
        <link_name>base_link</link_name>
        <control_joint_name>right_elevon_joint</control_joint_name>
        <control_joint_rad_to_cl>-1.0</control_joint_rad_to_cl>
        <robotNamespace/>
        <windSubTopic>world_wind</windSubTopic>
      </plugin>
      <plugin name='elevator_lift' filename='libLiftDragPlugin.so'>
        <a0>-0.2</a0>
        <cla>4.752798721</cla>
        <cda>0.6417112299</cda>
        <cma>0.0</cma>
        <alpha_stall>0.3391428111</alpha_stall>
        <cla_stall>-3.85</cla_stall>
        <cda_stall>-0.9233984055</cda_stall>
        <cma_stall>0</cma_stall>
        <cp>-0.5 0 0</cp>
        <area>0.01</area>
        <air_density>1.2041</air_density>
        <forward>1 0 0</forward>
        <upward>0 0 1</upward>
        <link_name>base_link</link_name>
        <control_joint_name>elevator_joint</control_joint_name>
        <control_joint_rad_to_cl>-12.0</control_joint_rad_to_cl>
        <robotNamespace/>
        <windSubTopic>world_wind</windSubTopic>
      </plugin>
      <plugin name='rudder_lift' filename='libLiftDragPlugin.so'>
        <a0>0.0</a0>
        <cla>4.752798721</cla>
        <cda>0.6417112299</cda>
        <cma>0.0.</cma>
        <alpha_stall>0.3391428111</alpha_stall>
        <cla_stall>-3.85</cla_stall>
        <cda_stall>-0.9233984055</cda_stall>
        <cma_stall>0</cma_stall>
        <cp>-0.5 0 0.05</cp>
        <area>0.02</area>
        <air_density>1.2041</air_density>
        <forward>1 0 0</forward>
        <upward>0 1 0</upward>
        <link_name>base_link</link_name>
        <robotNamespace/>
        <windSubTopic>world_wind</windSubTopic>
      </plugin>
      <plugin name='front_right_motor_model' filename='libgazebo_motor_model.so'>
        <robotNamespace/>
        <jointName>rotor_0_joint</jointName>
        <linkName>rotor_0</linkName>
        <turningDirection>ccw</turningDirection>
        <timeConstantUp>0.0125</timeConstantUp>
        <timeConstantDown>0.025</timeConstantDown>
        <maxRotVelocity>1500</maxRotVelocity>
        <motorConstant>2e-05</motorConstant>
        <momentConstant>0.06</momentConstant>
        <commandSubTopic>/gazebo/command/motor_speed</commandSubTopic>
        <motorNumber>0</motorNumber>
        <rotorDragCoefficient>0.000106428</rotorDragCoefficient>
        <rollingMomentCoefficient>1e-06</rollingMomentCoefficient>
        <motorSpeedPubTopic>/motor_speed/0</motorSpeedPubTopic>
        <rotorVelocitySlowdownSim>20</rotorVelocitySlowdownSim>
      </plugin>
      <plugin name='back_left_motor_model' filename='libgazebo_motor_model.so'>
        <robotNamespace/>
        <jointName>rotor_1_joint</jointName>
        <linkName>rotor_1</linkName>
        <turningDirection>ccw</turningDirection>
        <timeConstantUp>0.0125</timeConstantUp>
        <timeConstantDown>0.025</timeConstantDown>
        <maxRotVelocity>1500</maxRotVelocity>
        <motorConstant>2e-05</motorConstant>
        <momentConstant>0.06</momentConstant>
        <commandSubTopic>/gazebo/command/motor_speed</commandSubTopic>
        <motorNumber>1</motorNumber>
        <rotorDragCoefficient>0.000106428</rotorDragCoefficient>
        <rollingMomentCoefficient>1e-06</rollingMomentCoefficient>
        <motorSpeedPubTopic>/motor_speed/1</motorSpeedPubTopic>
        <rotorVelocitySlowdownSim>20</rotorVelocitySlowdownSim>
      </plugin>
      <plugin name='front_left_motor_model' filename='libgazebo_motor_model.so'>
        <robotNamespace/>
        <jointName>rotor_2_joint</jointName>
        <linkName>rotor_2</linkName>
        <turningDirection>cw</turningDirection>
        <timeConstantUp>0.0125</timeConstantUp>
        <timeConstantDown>0.025</timeConstantDown>
        <maxRotVelocity>1500</maxRotVelocity>
        <motorConstant>2e-05</motorConstant>
        <momentConstant>0.06</momentConstant>
        <commandSubTopic>/gazebo/command/motor_speed</commandSubTopic>
        <motorNumber>2</motorNumber>
        <rotorDragCoefficient>0.000106428</rotorDragCoefficient>
        <rollingMomentCoefficient>1e-06</rollingMomentCoefficient>
        <motorSpeedPubTopic>/motor_speed/2</motorSpeedPubTopic>
        <rotorVelocitySlowdownSim>20</rotorVelocitySlowdownSim>
      </plugin>
      <plugin name='back_right_motor_model' filename='libgazebo_motor_model.so'>
        <robotNamespace/>
        <jointName>rotor_3_joint</jointName>
        <linkName>rotor_3</linkName>
        <turningDirection>cw</turningDirection>
        <timeConstantUp>0.0125</timeConstantUp>
        <timeConstantDown>0.025</timeConstantDown>
        <maxRotVelocity>1500</maxRotVelocity>
        <motorConstant>2e-05</motorConstant>
        <momentConstant>0.06</momentConstant>
        <commandSubTopic>/gazebo/command/motor_speed</commandSubTopic>
        <motorNumber>3</motorNumber>
        <rotorDragCoefficient>0.000106428</rotorDragCoefficient>
        <rollingMomentCoefficient>1e-06</rollingMomentCoefficient>
        <motorSpeedPubTopic>/motor_speed/3</motorSpeedPubTopic>
        <rotorVelocitySlowdownSim>20</rotorVelocitySlowdownSim>
      </plugin>
      <plugin name='puller_motor_model' filename='libgazebo_motor_model.so'>
        <robotNamespace/>
        <jointName>rotor_puller_joint</jointName>
        <linkName>rotor_puller</linkName>
        <turningDirection>cw</turningDirection>
        <timeConstantUp>0.0125</timeConstantUp>
        <timeConstantDown>0.025</timeConstantDown>
        <maxRotVelocity>3500</maxRotVelocity>
        <motorConstant>8.54858e-06</motorConstant>
        <maxRelativeAirspeed>30</maxRelativeAirspeed>
        <momentConstant>0.01</momentConstant>
        <commandSubTopic>/gazebo/command/motor_speed</commandSubTopic>
        <motorNumber>4</motorNumber>
        <rotorDragCoefficient>0.000106428</rotorDragCoefficient>
        <rollingMomentCoefficient>1e-06</rollingMomentCoefficient>
        <motorSpeedPubTopic>/motor_speed/4</motorSpeedPubTopic>
        <rotorVelocitySlowdownSim>20</rotorVelocitySlowdownSim>
      </plugin>
      <plugin name='groundtruth_plugin' filename='libgazebo_groundtruth_plugin.so'>
        <robotNamespace/>
      </plugin>
      <plugin name='magnetometer_plugin' filename='libgazebo_magnetometer_plugin.so'>
        <robotNamespace/>
        <pubRate>100</pubRate>
        <noiseDensity>0.0004</noiseDensity>
        <randomWalk>6.4e-06</randomWalk>
        <biasCorrelationTime>600</biasCorrelationTime>
        <magTopic>/mag</magTopic>
      </plugin>
      <plugin name='barometer_plugin' filename='libgazebo_barometer_plugin.so'>
        <robotNamespace/>
        <pubRate>50</pubRate>
        <baroTopic>/baro</baroTopic>
      </plugin>
      <plugin name='mavlink_interface' filename='libgazebo_mavlink_interface.so'>
        <robotNamespace/>
        <imuSubTopic>/imu</imuSubTopic>
        <magSubTopic>/mag</magSubTopic>
        <baroSubTopic>/baro</baroSubTopic>
        <mavlink_addr>INADDR_ANY</mavlink_addr>
        <mavlink_tcp_port>4560</mavlink_tcp_port>
        <mavlink_udp_port>14560</mavlink_udp_port>
        <serialEnabled>0</serialEnabled>
        <serialDevice>/dev/ttyACM0</serialDevice>
        <baudRate>921600</baudRate>
        <qgc_addr>INADDR_ANY</qgc_addr>
        <qgc_udp_port>14550</qgc_udp_port>
        <sdk_addr>INADDR_ANY</sdk_addr>
        <sdk_udp_port>14540</sdk_udp_port>
        <hil_mode>0</hil_mode>
        <hil_state_level>0</hil_state_level>
        <enable_lockstep>1</enable_lockstep>
        <use_tcp>1</use_tcp>
        <motorSpeedCommandPubTopic>/gazebo/command/motor_speed</motorSpeedCommandPubTopic>
        <control_channels>
          <channel name='rotor0'>
            <input_index>0</input_index>
            <input_offset>0</input_offset>
            <input_scaling>1500</input_scaling>
            <zero_position_disarmed>0</zero_position_disarmed>
            <zero_position_armed>0</zero_position_armed>
            <joint_control_type>velocity</joint_control_type>
            <joint_name>rotor_0_joint</joint_name>
          </channel>
          <channel name='rotor1'>
            <input_index>1</input_index>
            <input_offset>0</input_offset>
            <input_scaling>1500</input_scaling>
            <zero_position_disarmed>0</zero_position_disarmed>
            <zero_position_armed>0</zero_position_armed>
            <joint_control_type>velocity</joint_control_type>
            <joint_name>rotor_1_joint</joint_name>
          </channel>
          <channel name='rotor2'>
            <input_index>2</input_index>
            <input_offset>0</input_offset>
            <input_scaling>1500</input_scaling>
            <zero_position_disarmed>0</zero_position_disarmed>
            <zero_position_armed>0</zero_position_armed>
            <joint_control_type>velocity</joint_control_type>
            <joint_name>rotor_2_joint</joint_name>
          </channel>
          <channel name='rotor3'>
            <input_index>3</input_index>
            <input_offset>0</input_offset>
            <input_scaling>1500</input_scaling>
            <zero_position_disarmed>0</zero_position_disarmed>
            <zero_position_armed>0</zero_position_armed>
            <joint_control_type>velocity</joint_control_type>
            <joint_name>rotor_3_joint</joint_name>
          </channel>
          <channel name='rotor4'>
            <input_index>4</input_index>
            <input_offset>0</input_offset>
            <input_scaling>5500</input_scaling>
            <zero_position_disarmed>0</zero_position_disarmed>
            <zero_position_armed>0</zero_position_armed>
            <joint_control_type>velocity</joint_control_type>
            <joint_name>rotor_puller_joint</joint_name>
          </channel>
          <channel name='left_elevon'>
            <input_index>5</input_index>
            <input_offset>0</input_offset>
            <input_scaling>1</input_scaling>
            <zero_position_disarmed>0</zero_position_disarmed>
            <zero_position_armed>0</zero_position_armed>
            <joint_control_type>position_kinematic</joint_control_type>
            <joint_name>left_elevon_joint</joint_name>
          </channel>
          <channel name='right_elevon'>
            <input_index>6</input_index>
            <input_offset>0</input_offset>
            <input_scaling>1</input_scaling>
            <zero_position_disarmed>0</zero_position_disarmed>
            <zero_position_armed>0</zero_position_armed>
            <joint_control_type>position_kinematic</joint_control_type>
            <joint_name>right_elevon_joint</joint_name>
          </channel>
          <channel name='elevator'>
            <input_index>7</input_index>
            <input_offset>0</input_offset>
            <input_scaling>1</input_scaling>
            <zero_position_disarmed>0</zero_position_disarmed>
            <zero_position_armed>0</zero_position_armed>
            <joint_control_type>position_kinematic</joint_control_type>
            <joint_name>elevator_joint</joint_name>
          </channel>
        </control_channels>
      </plugin>
      <plugin name='gazebo_imu_plugin' filename='libgazebo_imu_plugin.so'>
        <robotNamespace/>
        <linkName>standard_vtol/imu_link</linkName>
        <imuTopic>/imu</imuTopic>
      </plugin>
      <static>0</static>
    </model>
    <state world_name='default'>
      <sim_time>14 520000000</sim_time>
      <real_time>14 810038039</real_time>
      <wall_time>1741908049 686403200</wall_time>
      <iterations>3630</iterations>
      <model name='asphalt_plane'>
        <pose>0 0 0 0 -0 0</pose>
        <scale>1 1 1</scale>
        <link name='link'>
          <pose>0 0 0 0 -0 0</pose>
          <velocity>0 0 0 0 -0 0</velocity>
          <acceleration>0 0 0 0 -0 0</acceleration>
          <wrench>0 0 0 0 -0 0</wrench>
        </link>
      </model>
      <model name='ground_plane'>
        <pose>0 0 0 0 -0 0</pose>
        <scale>1 1 1</scale>
        <link name='link'>
          <pose>0 0 0 0 -0 0</pose>
          <velocity>0 0 0 0 -0 0</velocity>
          <acceleration>0 0 0 0 -0 0</acceleration>
          <wrench>0 0 0 0 -0 0</wrench>
        </link>
      </model>
      <model name='standard_vtol'>
        <pose>1.00889 0.979998 0.143874 -7e-06 2e-06 3.7e-05</pose>
        <scale>1 1 1</scale>
        <link name='airspeed::link'>
          <pose>1.00889 0.979993 0.143881 3e-06 8e-06 3.7e-05</pose>
          <velocity>-2e-06 -1.5e-05 0.000221 0.000141 1.6e-05 0</velocity>
          <acceleration>0 -0 0 0 -0 0</acceleration>
          <wrench>0 -0 0 0 -0 0</wrench>
        </link>
        <link name='base_link'>
          <pose>1.00889 0.979998 0.143874 -7e-06 2e-06 3.7e-05</pose>
          <velocity>0 -9e-06 0.000207 9.1e-05 1.6e-05 0</velocity>
          <acceleration>0 0 0 0 -0 0</acceleration>
          <wrench>0 0 0 0 -0 0</wrench>
        </link>
        <link name='elevator'>
          <pose>1.00889 0.979994 0.143885 3e-06 -2e-06 3.7e-05</pose>
          <velocity>-2e-06 -1.5e-05 7.5e-05 0.000141 0.000308 0</velocity>
          <acceleration>-0.000438 -0.003762 0.057282 0.035197 0.076902 -2.6e-05</acceleration>
          <wrench>-0 -0 0 0 -0 0</wrench>
        </link>
        <link name='gps::link'>
          <pose>1.00889 0.979994 0.14388 3e-06 8e-06 3.7e-05</pose>
          <velocity>-2e-06 -1.5e-05 0.000221 0.000141 1.6e-05 0</velocity>
          <acceleration>0 -0 0 0 -0 0</acceleration>
          <wrench>0 -0 0 0 -0 0</wrench>
        </link>
        <link name='left_elevon'>
          <pose>1.00889 0.979993 0.143871 5e-06 0 3.7e-05</pose>
          <velocity>-1e-06 -1.5e-05 0.000206 0.000102 0.000159 0</velocity>
          <acceleration>-0.000227 -0.003768 0.059047 0.025484 0.039788 -2.6e-05</acceleration>
          <wrench>-0 -0 0 0 -0 0</wrench>
        </link>
        <link name='right_elevon'>
          <pose>1.00889 0.979993 0.143879 3e-06 8e-06 3.7e-05</pose>
          <velocity>0 -1.6e-05 0.000215 0.000249 0.000416 -0</velocity>
          <acceleration>3.9e-05 -0.003951 0.01645 0.06235 0.104018 -2.6e-05</acceleration>
          <wrench>0 -0 0 0 -0 0</wrench>
        </link>
        <link name='rotor_0'>
          <pose>1.3589 0.630006 0.213877 3e-06 8e-06 3e-05</pose>
          <velocity>-1e-06 -2.5e-05 0.000166 0.000141 1.6e-05 0</velocity>
          <acceleration>-0.00056 -0.00248 -0.000793 0.01246 1.4e-05 0</acceleration>
          <wrench>-3e-06 -1.2e-05 -4e-06 0 -0 0</wrench>
        </link>
        <link name='rotor_1'>
          <pose>0.658875 1.32998 0.213884 3e-06 8e-06 3e-05</pose>
          <velocity>-1e-06 -2.5e-05 0.000276 0.000141 1.6e-05 0</velocity>
          <acceleration>-0.00054 -0.002453 0.00793 0.012455 1.1e-05 0</acceleration>
          <wrench>-3e-06 -1.2e-05 4e-05 0 -0 0</wrench>
        </link>
        <link name='rotor_2'>
          <pose>1.35888 1.33001 0.213879 3e-06 8e-06 3e-05</pose>
          <velocity>-1e-06 -2.5e-05 0.000265 0.000141 1.6e-05 0</velocity>
          <acceleration>-0.000537 -0.002472 0.007915 0.012422 -3.1e-05 -0</acceleration>
          <wrench>-3e-06 -1.2e-05 4e-05 0 -0 0</wrench>
        </link>
        <link name='rotor_3'>
          <pose>0.658901 0.62998 0.213882 3e-06 8e-06 3e-05</pose>
          <velocity>-1e-06 -2.5e-05 0.000177 0.000141 1.6e-05 0</velocity>
          <acceleration>-0.000559 -0.002446 -0.00077 0.012385 2.1e-05 -0</acceleration>
          <wrench>-3e-06 -1.2e-05 -4e-06 0 -0 0</wrench>
        </link>
        <link name='rotor_puller'>
          <pose>0.788887 0.979985 0.143882 0.762137 1.56971 0.762174</pose>
          <velocity>-2e-06 -1.5e-05 0.000225 9.1e-05 1.6e-05 0</velocity>
          <acceleration>-0.000549 -0.001581 0.003564 -2e-06 3.2e-05 0.003043</acceleration>
          <wrench>-3e-06 -8e-06 1.8e-05 0 -0 0</wrench>
        </link>
        <link name='rudder'>
          <pose>1.00889 0.980354 0.143882 0.007212 8e-06 3.7e-05</pose>
          <velocity>-2e-06 1e-05 0.000221 0.00065 1.6e-05 0</velocity>
          <acceleration>-0 0 -0 0 -0 0</acceleration>
          <wrench>-0 0 -0 0 -0 0</wrench>
        </link>
        <link name='standard_vtol/imu_link'>
          <pose>1.00889 0.979993 0.143881 1e-06 8e-06 3.7e-05</pose>
          <velocity>-2e-06 -1.5e-05 0.000221 0.000141 1.6e-05 0</velocity>
          <acceleration>0 0 0 0 -0 0</acceleration>
          <wrench>0 0 0 0 -0 0</wrench>
        </link>
      </model>
      <light name='sun'>
        <pose>0 0 10 0 -0 0</pose>
      </light>
    </state>
    <gui fullscreen='0'>
      <camera name='user_camera'>
        <pose>5.30892 -5.46287 2.14367 0 0.275643 2.35619</pose>
        <view_controller>orbit</view_controller>
        <projection_type>perspective</projection_type>
      </camera>
    </gui>
  </world>
</sdf>
